<?xml version="1.0" ?>
<mujoco model="ultra_simple">
  <compiler angle="radian" meshdir="/home/ben/all_projects/SO-ARM100/Simulation/SO101/assets" autolimits="true"/>
  
  <option gravity="0 0 -9.81" />
  
  <default>
    <default class="so101_new_calib">
      <joint damping="1" frictionloss="0.1" armature="0.005"/>
      <position kp="50"/>
      <default class="visual">
        <geom type="mesh" contype="0" conaffinity="0" group="2"/>
      </default>
      <default class="collision">
        <geom group="3" contype="1" conaffinity="1"/>
      </default>
    </default>
    <default class="sts3215">
      <geom contype="0" conaffinity="0"/>
      <joint damping="0.60" frictionloss="0.052" armature="0.028"/>
      <position kp="17.8"/>
    </default>
  </default>

  <asset>
    <!-- Minimal required meshes and materials -->
    <mesh file="rotation_pitch_so101_v1.stl"/>
    <mesh file="moving_jaw_so101_v1.stl"/>
    <mesh file="sts3215_03a_v1.stl"/>
    <mesh file="motor_holder_so101_wrist_v1.stl"/>
    <mesh file="wrist_roll_follower_so101_v1.stl"/>
    <mesh file="base_so101_v2.stl"/>
    <mesh file="under_arm_so101_v1.stl"/>
    <mesh file="wrist_roll_pitch_so101_v2.stl"/>
    <mesh file="waveshare_mounting_plate_so101_v2.stl"/>
    <mesh file="sts3215_03a_no_horn_v1.stl"/>
    <mesh file="motor_holder_so101_base_v1.stl"/>
    <mesh file="base_motor_holder_so101_v1.stl"/>
    <mesh file="upper_arm_so101_v1.stl"/>
    <material name="robot_mat" rgba="0.7 0.7 0.7 1"/>
  </asset>

  <worldbody>
    <!-- Ground -->
    <geom name="floor" type="plane" size="2 2 0.1" rgba="0.8 0.9 1 1" contype="1" conaffinity="1" />
    
    <!-- Robot base only (ultra minimal) -->
    <body name="base" pos="0 0 -0.03" quat="1 0 0 0" childclass="so101_new_calib">
      <inertial pos="0.020739 0.00204287 0.065966" mass="0.147" fullinertia="0.000136117 0.000114686 0.000130364 4.59787e-07 9.75275e-08 -4.97151e-06"/>
      <geom type="mesh" class="visual" pos="0.0207909 0.0221255 0.0300817" mesh="base_so101_v2" material="robot_mat"/>
      <site name="base" pos="0.020791 0.0157608 0.0324817"/>
      
      <body name="shoulder" pos="0.0207909 -0.0230745 0.0948817" quat="7.88629e-16 -0.707107 -0.707107 7.69003e-16">
        <joint axis="0 0 1" name="1" type="hinge" range="-1.9 1.9" class="sts3215"/>
        <inertial pos="-0.0307604 -1.66727e-05 -0.0252713" mass="0.100006" fullinertia="8.3759e-05 8.10403e-05 2.39783e-05 7.55525e-08 -1.16342e-06 1.54663e-07"/>
        <geom type="mesh" class="collision" pos="-0.0303992 0.000422241 -0.0417" quat="0.5 0.5 0.5 -0.5" mesh="sts3215_03a_v1" material="robot_mat"/>
        
        <body name="upper_arm" pos="-0.0303992 -0.0182778 -0.0542" quat="0.5 -0.5 -0.5 -0.5">
          <joint axis="0 0 1" name="2" type="hinge" range="-1.7 1.7" class="sts3215"/>
          <inertial pos="-0.0898471 -0.00838224 0.0184089" mass="0.103" fullinertia="4.08002e-05 0.000147318 0.000142487 -1.97819e-05 -4.03016e-08 8.97326e-09"/>
          <geom type="mesh" class="collision" pos="-0.065085 0.012 0.0182" mesh="upper_arm_so101_v1" material="robot_mat"/>
          
          <body name="lower_arm" pos="-0.11257 -0.028 0" quat="0.707107 0 0 0.707107">
            <joint axis="0 0 1" name="3" type="hinge" range="-1.7 1.5" class="sts3215"/>
            <inertial pos="-0.0980701 0.00324376 0.0182831" mass="0.104" fullinertia="2.87438e-05 0.000159844 0.00014529 7.41152e-06 1.26409e-06 -4.90188e-08"/>
            <geom type="mesh" class="collision" pos="-0.0648499 -0.032 0.0182" mesh="under_arm_so101_v1" material="robot_mat"/>
            
            <body name="wrist" pos="-0.1349 0.0052 0" quat="0.707107 0 0 -0.707107">
              <joint axis="0 0 1" name="4" type="hinge" range="-1.6 1.6" class="sts3215"/>
              <inertial pos="-0.000103312 -0.0386143 0.0281156" mass="0.079" fullinertia="3.68263e-05 2.5391e-05 2.1e-05 1.7893e-08 -5.28128e-08 3.6412e-06"/>
              <geom type="mesh" class="collision" pos="0 -0.028 0.0181" quat="0.5 -0.5 -0.5 -0.5" mesh="wrist_roll_pitch_so101_v2" material="robot_mat"/>
              
              <body name="gripper" pos="0 -0.0611 0.0181" quat="0 0 -0.707107 -0.707107">
                <joint axis="0 0 1" name="5" type="hinge" range="-2.7 2.7" class="sts3215"/>
                <inertial pos="0.000213627 0.000245138 -0.025187" mass="0.087" fullinertia="2.75087e-05 4.33657e-05 3.45059e-05 -3.35241e-07 -5.7352e-06 -5.17847e-08"/>
                <geom type="mesh" class="collision" pos="0 0 0.001" mesh="wrist_roll_follower_so101_v1" material="robot_mat"/>
                <site name="gripper" pos="0 0 -0.095"/>
                
                <body name="moving_jaw" pos="0.0202 0.0188 -0.0234" quat="0.707107 0.707107 0 0">
                  <joint axis="0 0 1" name="6" type="hinge" range="-0.17 1.7" class="sts3215"/>
                  <inertial pos="-0.00157495 -0.0300244 0.0192755" mass="0.012" fullinertia="6.61427e-06 1.89032e-06 5.28738e-06 -3.19807e-07 -5.90717e-09 -1.09945e-07"/>
                  <geom type="mesh" class="collision" pos="0 0 0.0189" mesh="moving_jaw_so101_v1" material="robot_mat"/>
                </body>
              </body>
            </body>
          </body>
        </body>
      </body>
    </body>

    <!-- Simple cube -->
    <body name="cube" pos="0.01 -0.25 0.02">
        <joint name="cube_joint" type="free" />
        <inertial pos="0 0 0" mass="0.05" diaginertia="0.0008 0.0008 0.0008" />
        <geom name="cube_geom" type="box" size="0.0125 0.0125 0.0125" rgba="1 0 0 1" contype="1" conaffinity="1"/>
    </body>
  </worldbody>

  <actuator>
    <position class="sts3215" name="1" joint="1" forcerange="-3.35 3.35"/>
    <position class="sts3215" name="2" joint="2" forcerange="-3.35 3.35"/>
    <position class="sts3215" name="3" joint="3" forcerange="-3.35 3.35"/>
    <position class="sts3215" name="4" joint="4" forcerange="-3.35 3.35"/>
    <position class="sts3215" name="5" joint="5" forcerange="-3.35 3.35"/>
    <position class="sts3215" name="6" joint="6" forcerange="-3.35 3.35"/>
  </actuator>

</mujoco> 